Workbook

Sheet README & Legend
A1: Cytognosis Foundation — Funding & Opportunity Funnel
A2: Master data workbook · compiled 2026-05-30 · companion to Funding_Strategy_Master_2026-05-30.md
A5: HOW THIS WORKBOOK IS ORGANIZED
A6: Master — Funding Opportunities | B6: All scored funding/grant/accelerator/credit candidates that passed the eligibility gate, with the full metric schema.
A7: Meta-Sources | B7: The discovery/monitoring layer (portals, aggregators, newsletters) used to FIND opportunities and to power the weekly scraper. Not funders themselves.
A8: PAC & Advocacy | B8: Companion list of Patient Advocacy Council / partnership targets. OneMind is cross-listed here and in Master (funder+accelerator+PAC).
A9: Backup & Parked | B9: Promising-but-blocked or missing-data candidates: invitation-only, tenured-PI-only, partner-institution-only, for-profit/VC (PBC-phase), or unverifiable. Kept visible, clearly marked.
A10: Wave Action Plan | B10: Chronological do-list grouped by wave with the single next action and deadline for each priority target.
A12: THE FUNNEL (hierarchical, iterative filtering)
A13: Level 0 — Universe | B13: Widest net: existing 71 Monday entries + 6 research clusters + discovered adjacents (~150 raw).
A14: Level 1 — Eligibility gate | B14: Hard binary filters. E1 entity fit (nonprofit-eligible / clean PBC-path / partner). E2 stage fit (early/pre-seed/Day-1 OK; not revenue/tenure/invite-only-with-no-path). E3 geography (US or US-path). Result: PASS / BACKUP / EXCLUDE.
A15: Level 2 — Alignment & values score | B15: Four 0–5 axes -> composite FitScore 0–10 (formula). Advance if FitScore >= 6.0; 4.0–5.9 = monitor/opportunistic; < 4.0 = deprioritize.
A16: Level 3 — Opportunity economics | B16: For survivors: funding scale bucket, amounts, current status, process timeline, review mechanism.
A17: Level 4 — Wave assignment | B17: Combine fit x economics x deadline urgency x effort into Waves 0–3 (timing strategy).
A18: Backup rule | B18: Any promising candidate where a gate fails OR a key metric can't be verified is parked in Backup with the reason — never silently dropped.
A20: SCORING RUBRIC (0–5 each; FitScore is a formula)
A21: AI (col J) | B21: 5 = AI/ML is the core lens · 4 = major · 3 = one of several · 2 = minor/enabling · 1 = incidental · 0 = none
A22: Health/MH (col K) | B22: 5 = mental-health / precision-psychiatry core · 4 = health core · 3 = health-adjacent/biomedical · 2 = health among many · 1 = tangential · 0 = none
A23: Values (col L) | B23: Count of strong matches among {moonshot/Pasteur, open-science, mission/impact-driven, collaborative/consortia}, 0–5
A24: Stage-fit (col M) | B24: 5 = built for early/Day-1/pre-seed or FRO-style · 4 = nonprofit/early friendly · 3 = nonprofit-eligible but expects maturity/partner · 2 = needs faculty/partner or for-profit · 1 = tenured/invite-only · 0 = ineligible
A25: FitScore (col N) | B25: Formula: K/5×3 + L/5×2.5 + J/5×2 + M/5×2.5 (max 10). Health & Stage weighted highest, then Values, then AI.
A27: FUNDING SCALE BUCKETS (col R, from Typical $)
A28: Small | B28: <= $250K
A29: Medium | B29: $250K – $1.5M
A30: Large | B30: $1.5M – $10M
A31: Mega | B31: > $10M
A32: (n/a) | B32: Amount not yet verified — see Backup/notes
A34: WAVES (col X)
A35: Wave 0 — Now (≤4 wks) | B35: Imminent open deadlines with FitScore≥6 + zero-cost prerequisites (registrations, free credits, HBNet, FRO submission).
A36: Wave 1 — 1–3 months | B36: High-fit near-term deadlines and high-value rolling targets to start now.
A37: Wave 2 — 3–6 months | B37: Fall cycles & relationship-build-now/apply-later; recurring annual programs.
A38: Wave 3 — 6–18 months / PBC | B38: Large strategic processes, EU/intl consortia, and for-profit/PBC-contingent (SBIR, accelerators taking equity).
A40: DATA CONFIDENCE (col AE)
A41: High | B41: Verified on a live primary source on/around 2026-05-30.
A42: Med | B42: From a credible secondary source or partially confirmed; re-verify before acting.
A43: Low | B43: Unconfirmed / page didn't load / inferred — treat as a lead, verify first.
A45: REGISTRY (col AF) | B45: Existing = already on Monday Funding Opportunities board · Refresh = on board but status updated here · New = net-new this pass.
A46: Prior Status (col AG) | B46: Real application history: Applied-rejected / In progress / Alumnus-WARM / Not started / Planned / Missed.
A47: Access / Warm-Intro Path (col AH) | B47: The named person/relationship that opens the door — see the Network & Warm-Intro Map tab. 'WARM' = an existing relationship to activate.
A49: ITERATION LOG
...

Sheet Master — Funding Opportunities
A1: Master — Funding Opportunities (funnel-scored)
A2: FitScore is a live formula (col N). Scale Bucket is a live formula (col R). Sort/filter freely. See README & Legend.
A4: ID | B4: Opportunity (Org — Program) | C4: Funder Org | D4: Source Type | E4: Opportunity Type | F4: Instrument | G4: Eligibility (Nonprofit/Early) | H4: Geo | I4: L1 Gate | J4: AI | K4: Health/MH | L4: Values | M4: Stage-fit | N4: FitScore (0-10) | O4: Amount Min $ | P4: Amount Max $ | Q4: Amount Typical $ | R4: Scale Bucket | S4: Status | T4: Next Deadline / Window | U4: Deadline Type | V4: Process & Timeline | W4: Review | X4: Wave | Y4: Strategic Pairing | Z4: Insider / Access Path | AA4: Apply URL | AB4: Monitor / Opportunities URL | AC4: Feed Type | AD4: Mission Rationale | AE4: Data Conf. | AF4: Registry | AG4: Prior Status | AH4: Access / Warm-Intro Path
A5: F001 | B5: ARPA-H IGoR (AI mechanistic disease modeling) | C5: ARPA-H | D5: Government | E5: Program ISO | F5: grant (OT) | G5: Yes | H5: US | I5: PASS | J5: 5 | K5: 4 | L5: 4 | M5: 5 | N5: =ROUND(K5/5*3+L5/5*2.5+J5/5*2+M5/5*2.5,1) -> 8.9 | R5: =IF(Q5="","(n/a)",IF(Q5<=250000,"Small",IF(Q5<=1500000,"Medium",IF(Q5<=10000000,"Large","Mega")))) -> (n/a) | S5: Open | T5: Solution Summary 2026-06-25; full 2026-08-06 | U5: Single | V5: SS→encourage→full; 5yr/3-phase; AI-assisted triage | W5: program-officer | X5: 0 | Y5: ARPA-H PHO/HSF ISO | Z5: ARPANET-H hubs; ARPA-H Vitals | AA5: https://arpa-h.gov/explore-funding/programs/igor | AB5: https://arpa-h.gov/explore-funding/open-funding-opportunities | AC5: API(Grants.gov)+HTML | AD5: AI-powered multiscale mechanistic disease modeling = Cytoverse | AE5: High | AF5: New | AG5: Not started | AH5: ARPA-H Vitals; Ananth Grama federal network
A6: F002 | B6: NIMH BRAIN: Next-Gen Human Sensor Tech (RFA-MH-26-140, U01) | C6: NIH / NIMH | D6: Government | E6: Cooperative agreement | F6: grant | G6: Yes | H6: US | I6: PASS | J6: 4 | K6: 5 | L6: 4 | M6: 4 | N6: =ROUND(K6/5*3+L6/5*2.5+J6/5*2+M6/5*2.5,1) -> 8.6 | O6: 1000000 | P6: 2000000 | Q6: 1800000 | R6: =IF(Q6="","(n/a)",IF(Q6<=250000,"Small",IF(Q6<=1500000,"Medium",IF(Q6<=10000000,"Large","Mega")))) -> Large | S6: Open | T6: 2026-06-15 (recurs to 2027-06-15) | U6: Recurring | V6: 8-12wk prep; submit→review Nov→council Jan→start Apr | W6: peer_review | X6: 0 | Y6: NIMH R21; ARPA-H IGoR | Z6: BRAIN Initiative Alliance | AA6: https://grants.nih.gov/grants/guide/rfa-files/RFA-MH-26-140.html | AB6: https://braininitiative.nih.gov/funding/funding-opportunities | AC6: RSS(NIH Guide) | AD6: Optical/NIRS wearable, brain-behavior sync = exact Cytoscope | AE6: High | AF6: New
A7: F003 | B7: AWS Imagine Grant — Pathfinder (GenAI) | C7: Amazon Web Services | D7: Corporate | E7: Corporate grant | F7: grant+credits | G7: Yes | H7: US | I7: PASS | J7: 5 | K7: 3 | L7: 3 | M7: 4 | N7: =ROUND(K7/5*3+L7/5*2.5+J7/5*2+M7/5*2.5,1) -> 7.3 | O7: 100000 | P7: 300000 | Q7: 300000 | R7: =IF(Q7="","(n/a)",IF(Q7<=250000,"Small",IF(Q7<=1500000,"Medium",IF(Q7<=10000000,"Large","Mega")))) -> Medium | S7: Open | T7: Round 1 2026-06-05; R2 invite 07-14; award Dec | U7: Recurring | V7: 3-4wk prep; R1 Jun5→R2 Sep14→award Dec | W7: program-officer | X7: 0 | Y7: AWS Activate; NVIDIA | Z7: AWS Gen AI Innovation Center | AA7: https://apply.younoodle.com/showcase/competition/2026_aws_imagine_grant | AB7: https://aws.amazon.com/government-education/nonprofits/aws-imagine-grant-program/ | AC7: HTML | AD7: Edge/agentic AI biosensor+navigator = Pathfinder criteria | AE7: High | AF7: Refresh
A8: F004 | B8: NSF X-Labs — Topic 1 Sensing & Imaging (Phase 0) | C8: NSF (TIP) | D8: Government | E8: Other Transaction | F8: grant (OT) | G8: Yes | H8: US | I8: PASS | J8: 4 | K8: 3 | L8: 4 | M8: 5 | N8: =ROUND(K8/5*3+L8/5*2.5+J8/5*2+M8/5*2.5,1) -> 7.9 | O8: 1500000 | P8: 50000000 | Q8: 15000000 | R8: =IF(Q8="","(n/a)",IF(Q8<=250000,"Small",IF(Q8<=1500000,"Medium",IF(Q8<=10000000,"Large","Mega")))) -> Mega | S8: Open | T8: Offers due 2026-07-13 (solic. open to 2028) | U8: Single | V8: Phase0 ≤$1.5M/9-12mo→Phase1 ≤$50M/yr; dedicated team | W8: expert_committee | X8: 0 | Y8: Convergent Research FRO | Z8: Hervé Marie-Nelly co-submission | AA8: https://sam.gov/workspace/contract/opp/0da4e39df20f481ca9299b0edefe23d2/view | AB8: https://www.nsf.gov/funding/initiatives/nsf-x-labs | AC8: API(SAM.gov)+RSS | AD8: Adaptive fNIRS spectroscopy headset = Sensing&Imaging exact | AE8: High | AF8: Refresh | AG8: In progress | AH8: Joint submission w/ Hervé Marie-Nelly (ex-insitro)
A9: F005 | B9: Wellcome Leap — Health Breakthrough Network (HBNet) membership | C9: Wellcome Leap | D9: FRO / Moonshot | E9: Network access | F9: in-kind | G9: Yes | H9: Intl/US | I9: PASS | J9: 0 | K9: 0 | L9: 5 | M9: 5 | N9: =ROUND(K9/5*3+L9/5*2.5+J9/5*2+M9/5*2.5,1) -> 5 | R9: =IF(Q9="","(n/a)",IF(Q9<=250000,"Small",IF(Q9<=1500000,"Medium",IF(Q9<=10000000,"Large","Mega")))) -> (n/a) | S9: Rolling | T9: Always open (do now) | U9: Rolling | V9: Email HBNet@wellcomeleap.org; sign MARFA/CORFA | W9: internal_panel | X9: 0 | Y9: All Wellcome Leap programs | Z9: HBNet@wellcomeleap.org | AA9: https://wellcomeleap.org/wellcome-leap-hbnet/ | AB9: https://wellcomeleap.org/ | AC9: Newsletter | AD9: Free prerequisite that unlocks every Leap program | AE9: High | AF9: New | AG9: Emailed HBNet Dec 15 2025 + reminder Jan 26 2026 — NO RESPONSE | AH9: Escalate: via an HBNet member institution (Manchester/Madhvi?, McLean, Mt Sinai) or a Program Director (e.g., Susanne Ahmari/MCPsych); the shared inbox is unresponsive
A10: F006 | B10: Convergent Research — FRO idea submission | C10: Convergent Research | D10: FRO / Moonshot | E10: FRO incubation | F10: grant (match) | G10: Yes | H10: US/UK | I10: PASS | J10: 4 | K10: 4 | L10: 5 | M10: 5 | N10: =ROUND(K10/5*3+L10/5*2.5+J10/5*2+M10/5*2.5,1) -> 9 | O10: 10000000 | P10: 50000000 | Q10: 25000000 | R10: =IF(Q10="","(n/a)",IF(Q10<=250000,"Small",IF(Q10<=1500000,"Medium",IF(Q10<=10000000,"Large","Mega")))) -> Mega | S10: Rolling | T10: Always open (no deadline) | U10: Rolling | V10: Abstract→eval→funder match→incubate (6-18mo) | W10: internal_panel | X10: 0 | Y10: NSF X-Labs; Schmidt/Astera | Z10: Adam Marblestone network; FAS.org | AA10: https://noteforms.com/forms/fro-abstract-submissions-uyswk3 | AB10: https://www.convergentresearch.org/get-involved | AC10: Newsletter | AD10: Open Cytoverse atlas is textbook FRO; $10M+ anchor | AE10: High | AF10: Refresh | AG10: Not started | AH10: Adam Marblestone / FAS FRO network
A11: F007 | B11: Anthropic — AI for Science (Claude credits) | C11: Anthropic | D11: Corporate | E11: Compute credits | F11: credits | G11: Yes | H11: Intl | I11: PASS | J11: 5 | K11: 4 | L11: 4 | M11: 5 | N11: =ROUND(K11/5*3+L11/5*2.5+J11/5*2+M11/5*2.5,1) -> 8.9 | O11: 20000 | P11: 50000 | Q11: 30000 | R11: =IF(Q11="","(n/a)",IF(Q11<=250000,"Small",IF(Q11<=1500000,"Medium",IF(Q11<=10000000,"Large","Mega")))) -> Small | S11: Rolling | T11: Monthly (1st Monday) | U11: Rolling | V11: 2-4wk; monthly decision; 6-mo credit validity | W11: program-officer | X11: 0 | Y11: Cohere; NAIRR | Z11: Claude for Nonprofits (already granted) | AA11: https://www.anthropic.com/news/ai-for-science-program | AB11: https://www.anthropic.com/news/ai-for-science-program | AC11: HTML | AD11: Low-friction credits for Cytoverse FM + Cytonome | AE11: High | AF11: Refresh
A12: F008 | B12: NAIRR Pilot — GPU compute allocation | C12: NSF / NAIRR | D12: Government | E12: Compute access | F12: in-kind | G12: Yes | H12: US | I12: PASS | J12: 5 | K12: 3 | L12: 4 | M12: 4 | N12: =ROUND(K12/5*3+L12/5*2.5+J12/5*2+M12/5*2.5,1) -> 7.8 | R12: =IF(Q12="","(n/a)",IF(Q12<=250000,"Small",IF(Q12<=1500000,"Medium",IF(Q12<=10000000,"Large","Mega")))) -> (n/a) | S12: Rolling | T12: Quarterly review cycles | U12: Rolling | V12: Apply→quarterly allocation; DOE-lab GPU time | W12: internal_panel | X12: 0 | Y12: Anthropic; Lambda | Z12: — | AA12: https://nairrpilot.org/opportunities/allocations | AB12: https://nairrpilot.org/opportunities | AC12: HTML | AD12: Cleanest nonprofit path to large GPU for Cytoverse training | AE12: High | AF12: New
A13: F009 | B13: ARPA-H — Proactive Health Office (PHO) ISO | C13: ARPA-H | D13: Government | E13: Mission Office ISO | F13: grant (OT) | G13: Yes | H13: US | I13: PASS | J13: 2 | K13: 5 | L13: 4 | M13: 5 | N13: =ROUND(K13/5*3+L13/5*2.5+J13/5*2+M13/5*2.5,1) -> 8.3 | O13: 2000000 | P13: 20000000 | Q13: 5000000 | R13: =IF(Q13="","(n/a)",IF(Q13<=250000,"Small",IF(Q13<=1500000,"Medium",IF(Q13<=10000000,"Large","Mega")))) -> Large | S13: Rolling | T13: Solution Summaries rolling to 2029-03-05 | U13: Rolling | V13: SS→~4.5mo encourage→45d full→~8-9mo cash | W13: program-officer | X13: 1 | Y13: ARPA-H IGoR; DELPHI | Z13: ARPA-H Vitals; PHO PM office | AA13: https://sam.gov/opp/a5b72db5139040f8b2a1dcc2d2c96733/view | AB13: https://arpa-h.gov/explore-funding/open-funding-opportunities | AC13: API(SAM.gov) | AD13: 'Prevent people becoming patients' = proactive health mission | AE13: High | AF13: Refresh | AG13: Not started | AH13: ARPA-H Vitals; Ananth Grama
A14: F010 | B14: ARPA-H — Health Science Futures (HSF) ISO | C14: ARPA-H | D14: Government | E14: Mission Office ISO | F14: grant (OT) | G14: Yes | H14: US | I14: PASS | J14: 4 | K14: 4 | L14: 4 | M14: 5 | N14: =ROUND(K14/5*3+L14/5*2.5+J14/5*2+M14/5*2.5,1) -> 8.5 | O14: 2000000 | P14: 20000000 | Q14: 5000000 | R14: =IF(Q14="","(n/a)",IF(Q14<=250000,"Small",IF(Q14<=1500000,"Medium",IF(Q14<=10000000,"Large","Mega")))) -> Large | S14: Rolling | T14: Rolling to 2029-03-05 | U14: Rolling | V14: SS→encourage→full; ~8-9mo to cash | W14: program-officer | X14: 1 | Y14: ARPA-H PHO; IGoR | Z14: ARPA-H Vitals | AA14: https://sam.gov/opp/29c3ac2ea6754d1f897f9c71204c0eea/view | AB14: https://arpa-h.gov/explore-funding/open-funding-opportunities | AC14: API(SAM.gov) | AD14: AI×biology + multi-scale modeling = Cytoverse | AE14: High | AF14: Refresh | AG14: Not started | AH14: ARPA-H Vitals
A15: F011 | B15: NIMH — Parent R21 (computational psychiatry pilot) | C15: NIH / NIMH | D15: Government | E15: R-series grant | F15: grant | G15: Yes | H15: US | I15: PASS | J15: 4 | K15: 5 | L15: 4 | M15: 4 | N15: =ROUND(K15/5*3+L15/5*2.5+J15/5*2+M15/5*2.5,1) -> 8.6 | O15: 200000 | P15: 275000 | Q15: 275000 | R15: =IF(Q15="","(n/a)",IF(Q15<=250000,"Small",IF(Q15<=1500000,"Medium",IF(Q15<=10000000,"Large","Mega")))) -> Medium | S15: Rolling | T15: Std dates Feb/Jun/Oct | U15: Recurring | V15: ~9-12mo submit→award; 2yr / ≤$275K | W15: peer_review | X15: 1 | Y15: NIMH U01/R34 | Z15: NIMH program officer (DTR) | AA15: https://grants.nih.gov/funding/activity-codes/R21 | AB15: https://grants.nih.gov/grants/guide | AC15: RSS(NIH Guide) | AD15: Ideal first NIH grant: biotyping/biomarker pilot | AE15: High | AF15: New
A16: F012 | B16: NIMH BRAIN: Data Archives (RFA-MH-25-110, R24) | C16: NIH / NIMH | D16: Government | E16: R24 grant | F16: grant | G16: Yes | H16: US | I16: PASS | J16: 3 | K16: 5 | L16: 5 | M16: 4 | N16: =ROUND(K16/5*3+L16/5*2.5+J16/5*2+M16/5*2.5,1) -> 8.7 | R16: =IF(Q16="","(n/a)",IF(Q16<=250000,"Small",IF(Q16<=1500000,"Medium",IF(Q16<=10000000,"Large","Mega")))) -> (n/a) | S16: Open | T16: through 2026-06-25 | U16: Recurring | V16: Std NIH timeline | W16: peer_review | X16: 1 | Y16: Cytoverse open data | Z16: BRAIN Alliance | AA16: https://grants.nih.gov/grants/guide/rfa-files/RFA-MH-25-110.html | AB16: https://braininitiative.nih.gov/funding/funding-opportunities | AC16: RSS(NIH Guide) | AD16: Funds Cytoverse as open FAIR psychiatric data archive | AE16: Med | AF16: New
A17: F013 | B17: NIMH BRAIN: Health-Equity Tech Partnerships (RFA-NS-25-016, R34) | C17: NIH / NIMH | D17: Government | E17: R34 planning grant | F17: grant | G17: Yes | H17: US | I17: PASS | J17: 3 | K17: 5 | L17: 5 | M17: 4 | N17: =ROUND(K17/5*3+L17/5*2.5+J17/5*2+M17/5*2.5,1) -> 8.7 | Q17: 450000 | R17: =IF(Q17="","(n/a)",IF(Q17<=250000,"Small",IF(Q17<=1500000,"Medium",IF(Q17<=10000000,"Large","Mega")))) -> Medium | S17: Open | T17: through 2026-06-18 | U17: Recurring | V17: Planning grant ~2-3yr | W17: peer_review | X17: 1 | Y17: NIMH U01 | Z17: BRAIN Alliance | AA17: https://grants.nih.gov/grants/guide/rfa-files/RFA-NS-25-016.html | AB17: https://braininitiative.nih.gov/funding/funding-opportunities | AC17: RSS(NIH Guide) | AD17: Brain-tech + underserved communities framing | AE17: Med | AF17: New
A18: F014 | B18: Convergent Research / Renaissance — Emergent Ventures (bridge) | C18: Mercatus Center | D18: EA / Longtermist | E18: Micro-grant | F18: grant | G18: Yes | H18: Intl | I18: PASS | J18: 3 | K18: 3 | L18: 4 | M18: 5 | N18: =ROUND(K18/5*3+L18/5*2.5+J18/5*2+M18/5*2.5,1) -> 7.5 | O18: 10000 | P18: 50000 | Q18: 30000 | R18: =IF(Q18="","(n/a)",IF(Q18<=250000,"Small",IF(Q18<=1500000,"Medium",IF(Q18<=10000000,"Large","Mega")))) -> Small | S18: Rolling | T18: Rolling (~7-day turnaround) | U18: Rolling | V18: Email pitch→days-weeks | W18: program-officer | X18: 1 | Y18: Manifund; SFF | Z18: Tyler Cowen | AA18: https://www.mercatus.org/emergent-ventures | AB18: https://www.mercatus.org/emergent-ventures | AC18: HTML | AD18: Fast non-dilutive bridge + credibility for moonshot | AE18: High | AF18: Refresh
A19: F015 | B19: Patrick J. McGovern Foundation — Data Practice Accelerator | C19: Patrick J. McGovern Foundation | D19: Philanthropic | E19: Capacity grant | F19: grant | G19: Yes | H19: US/Intl | I19: PASS | J19: 4 | K19: 3 | L19: 4 | M19: 4 | N19: =ROUND(K19/5*3+L19/5*2.5+J19/5*2+M19/5*2.5,1) -> 7.4 | P19: 125000 | Q19: 125000 | R19: =IF(Q19="","(n/a)",IF(Q19<=250000,"Small",IF(Q19<=1500000,"Medium",IF(Q19<=10000000,"Large","Mega")))) -> Small | S19: Open | T19: ~2026-07-01 (rolling cohorts) | U19: Recurring | V19: Rolling EOI→cohort; ≤$125K + in-kind | W19: program-officer | X19: 1 | Y19: — | Z19: PJMF program officers | AA19: https://www.mcgovern.org/grants/ | AB19: https://www.mcgovern.org | AC19: HTML | AD19: AI-for-public-good data org; starter capital + capacity | AE19: Med | AF19: New
A20: F016 | B20: NVIDIA — Academic Grant Program (GPU hardware) | C20: NVIDIA | D20: Corporate | E20: Hardware grant | F20: in-kind | G20: Yes | H20: Intl | I20: PASS | J20: 5 | K20: 3 | L20: 3 | M20: 4 | N20: =ROUND(K20/5*3+L20/5*2.5+J20/5*2+M20/5*2.5,1) -> 7.3 | O20: 10000 | P20: 100000 | Q20: 50000 | R20: =IF(Q20="","(n/a)",IF(Q20<=250000,"Small",IF(Q20<=1500000,"Medium",IF(Q20<=10000000,"Large","Mega")))) -> Small | S20: Rolling | T20: Always open | U20: Rolling | V20: Apply→4-8wk review | W20: internal_panel | X20: 1 | Y20: NAIRR; Lambda | Z20: NVIDIA Inception | AA20: https://academicgrants.nvidia.com/academicgrantprogram/s/Application | AB20: https://www.nvidia.com/en-us/industries/higher-education-research/academic-grant-program/ | AC20: HTML | AD20: H100-class hardware for Cytoverse training + edge inference | AE20: High | AF20: New
A21: F017 | B21: Cohere Labs — Catalyst Grants (credits) | C21: Cohere | D21: Corporate | E21: Compute credits | F21: credits | G21: Yes | H21: Intl | I21: PASS | J21: 5 | K21: 3 | L21: 4 | M21: 4 | N21: =ROUND(K21/5*3+L21/5*2.5+J21/5*2+M21/5*2.5,1) -> 7.8 | R21: =IF(Q21="","(n/a)",IF(Q21<=250000,"Small",IF(Q21<=1500000,"Medium",IF(Q21<=10000000,"Large","Mega")))) -> (n/a) | S21: Rolling | T21: Always open | U21: Rolling | V21: Apply→rolling review; email labs@cohere.com | W21: internal_panel | X21: 1 | Y21: Anthropic AI for Science | Z21: — | AA21: https://cohere.com/research/grants/application | AB21: https://cohere.com/research/grants | AC21: HTML | AD21: Healthcare is explicit focus; on-device Cytonome fit | AE21: High | AF21: New
A22: F018 | B22: Microsoft — AI for Health (credits + collaboration) | C22: Microsoft | D22: Corporate | E22: Credits + collab | F22: in-kind | G22: Yes | H22: Intl | I22: PASS | J22: 5 | K22: 4 | L22: 4 | M22: 4 | N22: =ROUND(K22/5*3+L22/5*2.5+J22/5*2+M22/5*2.5,1) -> 8.4 | R22: =IF(Q22="","(n/a)",IF(Q22<=250000,"Small",IF(Q22<=1500000,"Medium",IF(Q22<=10000000,"Large","Mega")))) -> (n/a) | S22: Rolling | T22: Always open | U22: Rolling | V22: Apply→rolling team response | W22: program-officer | X22: 1 | Y22: Founders Hub (PBC) | Z22: MSR AI for Good Lab | AA22: https://www.microsoft.com/en-us/research/project/ai-for-health/ | AB22: https://www.microsoft.com/en-us/research/group/ai-for-good-research-lab/ | AC22: HTML | AD22: AI×health Azure credits + researcher collaboration | AE22: Med | AF22: New
A23: F019 | B23: OneMind — Rising Star Award | C23: One Mind | D23: Mental-Health Foundation | E23: Research grant | F23: grant | G23: Partner-only (faculty-equiv host) | H23: US | I23: BACKUP | J23: 4 | K23: 5 | L23: 5 | M23: 3 | N23: =ROUND(K23/5*3+L23/5*2.5+J23/5*2+M23/5*2.5,1) -> 8.6 | O23: 300000 | P23: 300000 | Q23: 300000 | R23: =IF(Q23="","(n/a)",IF(Q23<=250000,"Small",IF(Q23<=1500000,"Medium",IF(Q23<=10000000,"Large","Mega")))) -> Medium | S23: Watch | T23: Annual Feb–Apr (2026 closed 04-27) | U23: Recurring | V23: ~6-8wk; submit→Jul decision→Jan funds; 3yr/$300K | W23: expert_committee | X23: 2 | Y23: OneMind Accelerator/OMLEC | Z23: CSO Tahilia Rebello; OMLEC | AA23: https://onemind.org/what-we-do/one-mind-rising-star-academy/one-mind-rising-star-awards/ | AB23: https://onemind.org/ | AC23: HTML | AD23: Transdiagnostic precision psychiatry + AI biomarkers; needs academic-affiliated PI | AE23: High | AF23: New | AG23: Not started — needs academic-host PI | AH23: OneMind CSO Tahilia Rebello; OMLEC
A24: F020 | B24: Google.org — AI for Science Impact Challenge | C24: Google.org | D24: Corporate | E24: Grant + accelerator | F24: grant | G24: Yes | H24: Intl/US | I24: PASS | J24: 5 | K24: 4 | L24: 5 | M24: 4 | N24: =ROUND(K24/5*3+L24/5*2.5+J24/5*2+M24/5*2.5,1) -> 8.9 | O24: 500000 | P24: 3000000 | Q24: 1500000 | R24: =IF(Q24="","(n/a)",IF(Q24<=250000,"Small",IF(Q24<=1500000,"Medium",IF(Q24<=10000000,"Large","Mega")))) -> Medium | S24: Closed-next | T24: ~Q1 2027 (cycle just closed 05-01) | U24: Recurring | V24: 6-8wk prep; submit→~4mo decision | W24: program-officer | X24: 2 | Y24: Google GenAI Accelerator | Z24: — | AA24: https://www.google.org/impact-challenges/ai-science/ | AB24: https://blog.google/outreach-initiatives/google-org/ | AC24: HTML | AD24: 'GPS for biology' + open-source mandate = near-exact | AE24: High | AF24: Refresh
A25: F021 | B25: OpenAI Foundation — Life Sciences & Curing Diseases | C25: OpenAI Foundation | D25: Corporate | E25: Grant (cash) | F25: grant | G25: Path/nonprofit | H25: US | I25: PASS | J25: 5 | K25: 4 | L25: 4 | M25: 4 | N25: =ROUND(K25/5*3+L25/5*2.5+J25/5*2+M25/5*2.5,1) -> 8.4 | R25: =IF(Q25="","(n/a)",IF(Q25<=250000,"Small",IF(Q25<=1500000,"Medium",IF(Q25<=10000000,"Large","Mega")))) -> (n/a) | S25: Watch | T25: Mechanism expected H2 2026 | U25: Single | V25: Submit interest now; RFP forthcoming | W25: program-officer | X25: 2 | Y25: OpenAI MH grants | Z25: Jacob Trefethen (lead) | AA25: https://openaifoundation.org | AB25: https://openaifoundation.org | AC25: Newsletter | AD25: $1B program; neuro/Alzheimer's + open health data | AE25: Med | AF25: New
A26: F022 | B26: OpenAI — AI & Mental Health Research Grants | C26: OpenAI | D26: Corporate | E26: Research grant | F26: grant | G26: Yes | H26: Intl | I26: PASS | J26: 5 | K26: 5 | L26: 4 | M26: 4 | N26: =ROUND(K26/5*3+L26/5*2.5+J26/5*2+M26/5*2.5,1) -> 9 | O26: 5000 | P26: 100000 | Q26: 75000 | R26: =IF(Q26="","(n/a)",IF(Q26<=250000,"Small",IF(Q26<=1500000,"Medium",IF(Q26<=10000000,"Large","Mega")))) -> Small | S26: Watch | T26: ~Q4 2026 (closed Dec 2025) | U26: Recurring | V26: ~6wk; Jan decision | W26: program-officer | X26: 2 | Y26: OpenAI Foundation LS | Z26: — | AA26: https://openai.com/index/ai-mental-health-research-grants/ | AB26: https://openai.smapply.org | AC26: HTML | AD26: Direct AI × mental health; high signal, small $ | AE26: High | AF26: New
A27: F023 | B27: CZI Science — AI/GPU Compute RFA | C27: Chan Zuckerberg Initiative | D27: Philanthropic | E27: Compute (in-kind) | F27: in-kind | G27: Yes | H27: US | I27: PASS | J27: 5 | K27: 4 | L27: 5 | M27: 4 | N27: =ROUND(K27/5*3+L27/5*2.5+J27/5*2+M27/5*2.5,1) -> 8.9 | R27: =IF(Q27="","(n/a)",IF(Q27<=250000,"Small",IF(Q27<=1500000,"Medium",IF(Q27<=10000000,"Large","Mega")))) -> (n/a) | S27: Watch | T27: Cycle 2 TBD (Cycle 1 closed 2025-06-18) | U27: Recurring | V27: Rolling during open window | W27: peer_review | X27: 2 | Y27: CZI EOSS | Z27: sciencegrants@chanzuckerberg.com | AA27: https://chanzuckerberg.com/rfa/ | AB27: https://chanzuckerberg.com/science/science-funding/ | AC27: HTML | AD27: Virtual-cell / foundation-model biology; nonprofit-eligible | AE27: High | AF27: New | AG27: Not started | AH27: Angela Oliveira Pisco (Dir. Data Science, CZI; ex-insitro manager) — WARM
A28: F024 | B28: CZI Science — Essential Open Source Software (EOSS) Cycle 6 | C28: Chan Zuckerberg Initiative | D28: Philanthropic | E28: OSS grant | F28: grant | G28: Yes | H28: US/Intl | I28: PASS | J28: 4 | K28: 4 | L28: 5 | M28: 4 | N28: =ROUND(K28/5*3+L28/5*2.5+J28/5*2+M28/5*2.5,1) -> 8.5 | O28: 100000 | P28: 400000 | Q28: 250000 | R28: =IF(Q28="","(n/a)",IF(Q28<=250000,"Small",IF(Q28<=1500000,"Medium",IF(Q28<=10000000,"Large","Mega")))) -> Small | S28: Open | T28: LOI 2026-10-18 | U28: Recurring | V28: LOI Oct→invited full→2027 awards | W28: peer_review | X28: 2 | Y28: CZI AI/GPU RFA | Z28: — | AA28: https://chanzuckerberg.com/rfa/essential-open-source-software-for-science/ | AB28: https://chanzuckerberg.com/science/programs-resources/open-science/grants/ | AC28: HTML | AD28: Cytoverse open tools (Apache 2.0) near-perfect fit | AE28: High | AF28: New | AG28: Not started | AH28: Angela Oliveira Pisco (CZI) — WARM
A29: F025 | B29: McKnight — Technology Awards (neuro tools) | C29: McKnight Endowment for Neuroscience | D29: Philanthropic | E29: Innovation grant | F29: grant | G29: Yes | H29: US | I29: PASS | J29: 3 | K29: 5 | L29: 4 | M29: 3 | N29: =ROUND(K29/5*3+L29/5*2.5+J29/5*2+M29/5*2.5,1) -> 7.7 | Q29: 200000 | R29: =IF(Q29="","(n/a)",IF(Q29<=250000,"Small",IF(Q29<=1500000,"Medium",IF(Q29<=10000000,"Large","Mega")))) -> Small | S29: Watch | T29: Opens ~Aug 1 2026 | U29: Recurring | V29: Annual; ~$200K/yr x2 | W29: peer_review | X29: 2 | Y29: BBRF; Allen ADI | Z29: — | AA29: https://www.mcknight.org/programs/the-mcknight-endowment-fund-for-neuroscience/technology-awards/ | AB29: https://www.mcknight.org | AC29: HTML | AD29: 'New & unusual approaches to brain function' = Cytoscope | AE29: High | AF29: New
A30: F026 | B30: Tiny Blue Dot Foundation — Perception Box (Round 5) | C30: Tiny Blue Dot Foundation | D30: Philanthropic | E30: Research grant | F30: grant | G30: Yes (501c3) | H30: Intl | I30: PASS | J30: 3 | K30: 5 | L30: 4 | M30: 4 | N30: =ROUND(K30/5*3+L30/5*2.5+J30/5*2+M30/5*2.5,1) -> 8.2 | P30: 900000 | Q30: 500000 | R30: =IF(Q30="","(n/a)",IF(Q30<=250000,"Small",IF(Q30<=1500000,"Medium",IF(Q30<=10000000,"Large","Mega")))) -> Medium | S30: Watch | T30: ~Sep LOI (annual) | U30: Recurring | V30: LOI Sep→Dec select→spring full; ≤$900K/3yr | W30: peer_review | X30: 2 | Y30: OneMind RSA | Z30: — | AA30: https://www.tinybluedotfoundation.org/research/rfp | AB30: https://www.tinybluedotfoundation.org/ | AC30: HTML | AD30: Brain constructs reality + AI/neuromod/wearables; 501c3 eligible | AE30: High | AF30: New
A31: F027 | B31: Simons Foundation — SFARI New Ideas Award | C31: Simons Foundation | D31: Philanthropic | E31: Research grant | F31: grant | G31: Yes (independent PI) | H31: US/Intl | I31: PASS | J31: 2 | K31: 4 | L31: 4 | M31: 3 | N31: =ROUND(K31/5*3+L31/5*2.5+J31/5*2+M31/5*2.5,1) -> 6.7 | O31: 100000 | P31: 300000 | Q31: 200000 | R31: =IF(Q31="","(n/a)",IF(Q31<=250000,"Small",IF(Q31<=1500000,"Medium",IF(Q31<=10000000,"Large","Mega")))) -> Small | S31: Rolling | T31: LOI rolling from 2026-04-29 | U31: Rolling | V31: LOI→3-4mo decision | W31: peer_review | X31: 2 | Y31: SCGB | Z31: — | AA31: https://www.sfari.org/grant/new-ideas-request-for-applications/ | AB31: https://www.sfari.org/funding-opportunities/ | AC31: HTML | AD31: Autism/NDD precision phenotyping adjacent to pilot | AE31: High | AF31: New
A32: F028 | B32: CIAPM — Precision Medicine Research (CA) | C32: CA Initiative to Advance Precision Medicine | D32: Government | E32: State grant | F32: grant | G32: Partial (CA-based) | H32: CA | I32: PASS | J32: 4 | K32: 5 | L32: 4 | M32: 3 | N32: =ROUND(K32/5*3+L32/5*2.5+J32/5*2+M32/5*2.5,1) -> 8.1 | O32: 1200000 | P32: 2000000 | Q32: 1500000 | R32: =IF(Q32="","(n/a)",IF(Q32<=250000,"Small",IF(Q32<=1500000,"Medium",IF(Q32<=10000000,"Large","Mega")))) -> Medium | S32: Watch | T32: Next cycle on CA budget (~summer) | U32: Recurring | V32: LOI→full→award; 2.5yr | W32: internal_panel | X32: 2 | Y32: UCSF AIM; Stanford PMHW | Z32: CHHS; CA partners | AA32: https://ciapm-chhs.submittable.com/submit | AB32: https://ciapm.chhs.ca.gov/activity/news.html | AC32: HTML | AD32: Depression precision medicine + equity; CA HQ is an asset | AE32: High | AF32: New
A33: F029 | B33: Fast Forward — Tech-Nonprofit Accelerator (2027) | C33: Fast Forward | D33: Philanthropic | E33: Accelerator + grant | F33: grant | G33: Yes (tech-nonprofit) | H33: Intl | I33: PASS | J33: 4 | K33: 3 | L33: 4 | M33: 5 | N33: =ROUND(K33/5*3+L33/5*2.5+J33/5*2+M33/5*2.5,1) -> 7.9 | O33: 25000 | Q33: 25000 | R33: =IF(Q33="","(n/a)",IF(Q33<=250000,"Small",IF(Q33<=1500000,"Medium",IF(Q33<=10000000,"Large","Mega")))) -> Small | S33: Watch | T33: Apps 2026-07-30 to 09-08 | U33: Recurring | V33: Apply Jul-Sep→Feb-May 2027 program; $25K+ unrestricted | W33: internal_panel | X33: 2 | Y33: Google.org GenAI | Z33: ffwd.org newsletters | AA33: https://www.ffwd.org/accelerator | AB33: https://www.ffwd.org/accelerator | AC33: Newsletter | AD33: Only accelerator built for AI/tech nonprofits; exact 501c3 fit | AE33: High | AF33: Refresh
A34: F030 | B34: Speculative Technologies — Brains Accelerator (2027) | C34: Speculative Technologies | D34: FRO / Moonshot | E34: Accelerator | F34: in-kind | G34: Yes (individual) | H34: US | I34: PASS | J34: 4 | K34: 3 | L34: 5 | M34: 5 | N34: =ROUND(K34/5*3+L34/5*2.5+J34/5*2+M34/5*2.5,1) -> 8.4 | R34: =IF(Q34="","(n/a)",IF(Q34<=250000,"Small",IF(Q34<=1500000,"Medium",IF(Q34<=10000000,"Large","Mega")))) -> (n/a) | S34: Watch | T34: Apps open ~Oct 2026 | U34: Recurring | V34: 15wk part-time; connects to FRO funders | W34: internal_panel | X34: 2 | Y34: Convergent FRO; Renaissance | Z34: Ben Reinhardt | AA34: https://spec.tech/brains | AB34: https://spec.tech/brains | AC34: Newsletter | AD34: Develop Cytoverse/Cytoscope as coordinated research program | AE34: High | AF34: Refresh | AG34: Applied — rejected | AH34: Reapply 2027 with reframe; Ben Reinhardt
A35: F031 | B35: Astera Institute — Residency (Spring 2027) | C35: Astera Institute | D35: FRO / Moonshot | E35: Residency | F35: fellowship | G35: Yes (individual) | H35: US (onsite Emeryville) | I35: PASS | J35: 5 | K35: 4 | L35: 5 | M35: 4 | N35: =ROUND(K35/5*3+L35/5*2.5+J35/5*2+M35/5*2.5,1) -> 8.9 | O35: 125000 | P35: 1500000 | Q35: 500000 | R35: =IF(Q35="","(n/a)",IF(Q35<=250000,"Small",IF(Q35<=1500000,"Medium",IF(Q35<=10000000,"Large","Mega")))) -> Medium | S35: Watch | T35: Next cycle ~fall 2026 (closed 04-19) | U35: Recurring | V35: Apply→admit; salary + ≤$1.5M project | W35: internal_panel | X35: 2 | Y35: Convergent FRO | Z35: Astera Substack | AA35: https://astera.org/residency/ | AB35: https://astera.org/residency/ | AC35: Newsletter | AD35: Neuro-AI + open science; pre-commercial; was prior denial | AE35: High | AF35: Refresh | AG35: Applied — rejected | AH35: Reapply Spring 2027; Neuro-AI/open-science framing
A36: F032 | B36: Activate — Cyclotron Road Fellowship (2027) | C36: Activate | D36: Philanthropic | E36: Fellowship | F36: fellowship | G36: Yes (individual, no equity) | H36: US | I36: PASS | J36: 2 | K36: 3 | L36: 4 | M36: 4 | N36: =ROUND(K36/5*3+L36/5*2.5+J36/5*2+M36/5*2.5,1) -> 6.6 | O36: 300000 | Q36: 300000 | R36: =IF(Q36="","(n/a)",IF(Q36<=250000,"Small",IF(Q36<=1500000,"Medium",IF(Q36<=10000000,"Large","Mega")))) -> Medium | S36: Watch | T36: Apps ~Oct 2026 | U36: Recurring | V36: >$300K/2yr stipend + R&D; no equity | W36: expert_committee | X36: 2 | Y36: NSF X-Labs | Z36: — | AA36: https://activate.org/apply | AB36: https://activate.org/the-fellowship | AC36: HTML | AD36: Hardware/sensor vertical for Cytoscope; founder-led | AE36: High | AF36: New
A37: F033 | B37: BBRF — NARSAD Young Investigator Grant | C37: Brain & Behavior Research Foundation | D37: Mental-Health Foundation | E37: Research grant | F37: grant | G37: Partial (institution host) | H37: US | I37: BACKUP | J37: 2 | K37: 5 | L37: 3 | M37: 3 | N37: =ROUND(K37/5*3+L37/5*2.5+J37/5*2+M37/5*2.5,1) -> 6.8 | O37: 70000 | P37: 70000 | Q37: 70000 | R37: =IF(Q37="","(n/a)",IF(Q37<=250000,"Small",IF(Q37<=1500000,"Medium",IF(Q37<=10000000,"Large","Mega")))) -> Small | S37: Watch | T37: Annual ~Feb | U37: Recurring | V37: Feb open→fall decision; $70K/2yr | W37: expert_committee | X37: 2 | Y37: NIMH R21 | Z37: — | AA37: https://bbrfoundation.org/grants-prizes/bbrf-young-investigator-grants | AB37: https://bbrfoundation.org/grants-prizes/grants | AC37: HTML | AD37: Dx tools/biomarkers for depression/anxiety/psychosis; needs faculty-equiv host | AE37: High | AF37: New
A38: F034 | B38: AFSP — Focus / Innovation Research Grants | C38: American Foundation for Suicide Prevention | D38: Mental-Health Foundation | E38: Research grant | F38: grant | G38: Yes (nonprofit) | H38: US | I38: PASS | J38: 2 | K38: 5 | L38: 3 | M38: 3 | N38: =ROUND(K38/5*3+L38/5*2.5+J38/5*2+M38/5*2.5,1) -> 6.8 | O38: 50000 | P38: 500000 | Q38: 125000 | R38: =IF(Q38="","(n/a)",IF(Q38<=250000,"Small",IF(Q38<=1500000,"Medium",IF(Q38<=10000000,"Large","Mega")))) -> Small | S38: Watch | T38: LOI ~Aug; full ~Nov-Dec | U38: Recurring | V38: LOI Aug→full Dec→May decision | W38: expert_committee | X38: 2 | Y38: NIMH | Z38: — | AA38: https://afsp.org/research-grant-information/ | AB38: https://afsp.org/research-grants/ | AC38: HTML | AD38: Suicide-risk biomarkers in-scope; nonprofit institution eligible | AE38: High | AF38: New
A39: F035 | B39: Coefficient Giving — Science & Global Health R&D | C39: Coefficient Giving (ex-Open Phil) | D39: Philanthropic | E39: Major grant | F39: grant | G39: Yes | H39: US/Intl | I39: PASS | J39: 2 | K39: 4 | L39: 4 | M39: 3 | N39: =ROUND(K39/5*3+L39/5*2.5+J39/5*2+M39/5*2.5,1) -> 6.7 | O39: 500000 | P39: 10000000 | Q39: 2000000 | R39: =IF(Q39="","(n/a)",IF(Q39<=250000,"Small",IF(Q39<=1500000,"Medium",IF(Q39<=10000000,"Large","Mega")))) -> Large | S39: Rolling | T39: Proactive / unsolicited (~1-2%) | U39: Rolling | V39: 1-2pg brief→PO response; 5-12mo | W39: program-officer | X39: 2 | Y39: EA Funds | Z39: science@coefficientgiving.org | AA39: https://coefficientgiving.org/apply-for-funding/ | AB39: https://coefficientgiving.org/funds/ | AC39: HTML | AD39: Big philanthropy; neglected-disease framing needed; cold path | AE39: High | AF39: Refresh | AG39: Planned | AH39: science@coefficientgiving.org (cold)
A40: F036 | B40: Google.org — Generative AI Accelerator | C40: Google.org | D40: Corporate | E40: Accelerator + grant | F40: grant | G40: Yes | H40: Intl/US | I40: PASS | J40: 5 | K40: 3 | L40: 4 | M40: 4 | N40: =ROUND(K40/5*3+L40/5*2.5+J40/5*2+M40/5*2.5,1) -> 7.8 | O40: 500000 | P40: 2000000 | Q40: 1000000 | R40: =IF(Q40="","(n/a)",IF(Q40<=250000,"Small",IF(Q40<=1500000,"Medium",IF(Q40<=10000000,"Large","Mega")))) -> Medium | S40: Watch | T40: ~fall 2026 (2025 cohort selected) | U40: Recurring | V40: Annual; 6-mo pro-bono + credits + ≥$500K | W40: program-officer | X40: 2 | Y40: Google.org AI for Science | Z40: — | AA40: https://impactchallenge.withgoogle.com/genaiaccelerator | AB40: https://blog.google/outreach-initiatives/google-org/ | AC40: HTML | AD40: GenAI for health; Cytonome on-device angle | AE40: Med | AF40: New
A41: F037 | B41: NSF Convergence Accelerator (next cohort) | C41: NSF (TIP) | D41: Government | E41: Cooperative agreement | F41: grant | G41: Yes | H41: US | I41: PASS | J41: 4 | K41: 3 | L41: 4 | M41: 4 | N41: =ROUND(K41/5*3+L41/5*2.5+J41/5*2+M41/5*2.5,1) -> 7.4 | O41: 750000 | P41: 5000000 | Q41: 2000000 | R41: =IF(Q41="","(n/a)",IF(Q41<=250000,"Small",IF(Q41<=1500000,"Medium",IF(Q41<=10000000,"Large","Mega")))) -> Large | S41: Watch | T41: Next DCL TBD | U41: Recurring | V41: Ideation→Ph1 ≤$750K→Ph2 ≤$5M | W41: peer_review | X41: 2 | Y41: NSF X-Labs | Z41: — | AA41: https://www.nsf.gov/funding/initiatives/convergence-accelerator | AB41: https://www.nsf.gov/funding/initiatives/convergence-accelerator | AC41: RSS(NSF) | AD41: Health+AI track if released; consortium model | AE41: Med | AF41: Existing
...

Sheet Funnel Summary
A1: Funnel Summary & Dashboard
A2: Live counts over the Master sheet (FitScore col N, Wave col X, Bucket col R, Gate col I).
A4: By Wave
A5: Category | B5: Count
A6: Wave 0 — Now (≤4 wks) | B6: =COUNTIF('Master — Funding Opportunities'!$X$5:$X$200,"0") -> 8
A7: Wave 1 — 1–3 months | B7: =COUNTIF('Master — Funding Opportunities'!$X$5:$X$200,"1") -> 12
A8: Wave 2 — 3–6 months | B8: =COUNTIF('Master — Funding Opportunities'!$X$5:$X$200,"2") -> 37
A9: Wave 3 — 6–18 mo / PBC | B9: =COUNTIF('Master — Funding Opportunities'!$X$5:$X$200,"3") -> 17
A10: Backup / Parked | B10: =COUNTIF('Master — Funding Opportunities'!$X$5:$X$200,"Backup") -> 17
A11: TOTAL rows | B11: =COUNTA('Master — Funding Opportunities'!$B$5:$B$200) -> 91
A13: By Funding-Scale Bucket
A14: Category | B14: Count
A15: Small (≤$250K) | B15: =COUNTIF('Master — Funding Opportunities'!$R$5:$R$200,"Small") -> 20
A16: Medium ($250K–1.5M) | B16: =COUNTIF('Master — Funding Opportunities'!$R$5:$R$200,"Medium") -> 23
A17: Large ($1.5–10M) | B17: =COUNTIF('Master — Funding Opportunities'!$R$5:$R$200,"Large") -> 15
A18: Mega (>$10M) | B18: =COUNTIF('Master — Funding Opportunities'!$R$5:$R$200,"Mega") -> 3
A19: Amount not yet verified | B19: =COUNTIF('Master — Funding Opportunities'!$R$5:$R$200,"(n/a)") -> 30
A21: By FitScore band
A22: Category | B22: Count
A23: Strong fit (≥8.0) | B23: =COUNTIF('Master — Funding Opportunities'!$N$5:$N$200,">=8") -> 31
A24: Good fit (6.0–7.9) | B24: =COUNTIFS('Master — Funding Opportunities'!$N$5:$N$200,">=6",'Master — Funding Opportunities'!$N$5:$N$200,"<8") -> 54
A25: Monitor (4.0–5.9) | B25: =COUNTIFS('Master — Funding Opportunities'!$N$5:$N$200,">=4",'Master — Funding Opportunities'!$N$5:$N$200,"<6") -> 6
A26: Deprioritize (<4.0) | B26: =COUNTIFS('Master — Funding Opportunities'!$N$5:$N$200,"<4",'Master — Funding Opportunities'!$N$5:$N$200,">0") -> 0
A28: By L1 Gate
A29: Category | B29: Count
A30: PASS | B30: =COUNTIF('Master — Funding Opportunities'!$I$5:$I$200,"PASS") -> 58
A31: BACKUP | B31: =COUNTIF('Master — Funding Opportunities'!$I$5:$I$200,"BACKUP") -> 33
A32: EXCLUDE | B32: =COUNTIF('Master — Funding Opportunities'!$I$5:$I$200,"EXCLUDE") -> 0
A34: By Source Type
A35: Category | B35: Count
A36: Government | B36: =COUNTIF('Master — Funding Opportunities'!$D$5:$D$200,"Government") -> 20
A37: Philanthropic | B37: =COUNTIF('Master — Funding Opportunities'!$D$5:$D$200,"Philanthropic") -> 23
A38: FRO / Moonshot | B38: =COUNTIF('Master — Funding Opportunities'!$D$5:$D$200,"FRO / Moonshot") -> 7
A39: Corporate | B39: =COUNTIF('Master — Funding Opportunities'!$D$5:$D$200,"Corporate") -> 17
A40: Mental-Health Foundation | B40: =COUNTIF('Master — Funding Opportunities'!$D$5:$D$200,"Mental-Health Foundation") -> 13
A41: EA / Longtermist | B41: =COUNTIF('Master — Funding Opportunities'!$D$5:$D$200,"EA / Longtermist") -> 3
A42: Venture Capital | B42: =COUNTIF('Master — Funding Opportunities'!$D$5:$D$200,"Venture Capital") -> 3
A43: Intergovernmental | B43: =COUNTIF('Master — Funding Opportunities'!$D$5:$D$200,"Intergovernmental") -> 2

Sheet Meta-Sources
A1: Meta-Sources — Discovery & Monitoring Layer
A2: Where opportunities are found / announced. 'Easy' API+RSS rows are the scraper backbone (Stage 2).
A4: ID | B4: Source | C4: Type | D4: Coverage | E4: Free/Paid | F4: Machine-readable feed | G4: Feed / API URL | H4: Update cadence | I4: Scrape feasibility | J4: Priority | K4: Notes (auth / keywords)
A5: S01 | B5: Grants.gov Search2 API | C5: Federal portal | D5: All US federal grants (~26 agencies) | E5: Free, no auth | F5: REST API (JSON, POST) | G5: https://api.grants.gov/v1/api/search2 | H5: Real-time | I5: Easy | J5: High | K5: No key. POST {keyword}. Backbone of scraper. Also RSS GG_NewOppByCategory.xml
A6: S02 | B6: SAM.gov Get Opportunities API v2 | C6: Federal portal | D6: All federal contract/OT/grant opps incl. ARPA-H, NSF X-Labs | E6: Free (API key) | F6: REST API (JSON) | G6: https://api.sam.gov/prod/opportunities/v2/search | H6: Real-time | I6: Easy | J6: High | K6: Register system acct → 1,000 req/day. Filter ptype=g + keywords
A7: S03 | B7: NIH Guide for Grants & Contracts | C7: Federal portal | D7: All NIH FOAs (RFA/PAR/PA/NOT) incl. NIMH/BRAIN | E7: Free | F7: RSS + XML web services | G7: https://grants.nih.gov/grants/guide/newsfeed/fundingopps.xml | H7: Weekly (Fri)+notices | I7: Easy | J7: High | K7: Filter activity code + IC=NIMH + keywords
A8: S04 | B8: NSF Funding Opportunities | C8: Federal portal | D8: All NSF directorates incl. TIP / X-Labs | E8: Free | F8: RSS | G8: https://www.nsf.gov/rss/rss_www_funding_search.xml | H8: Continuous | I8: Easy | J8: High | K8: Keywords: AI, neuroscience, sensing, open science
A9: S05 | B9: Federal Register API | C9: Federal portal | D9: Agency notices, RFIs, program announcements | E9: Free, no auth | F9: REST API (JSON/CSV) | G9: https://www.federalregister.gov/api/v1/documents.json | H9: Daily | I9: Easy | J9: Med | K9: type=NOTICE + term=funding opportunity
A10: S06 | B10: NIH RePORTER API | C10: Federal portal | D10: Funded NIH grants (competitive intel) | E10: Free, no auth | F10: REST API (POST) | G10: https://api.reporter.nih.gov/ | H10: Continuous | I10: Easy | J10: Med | K10: Who funds precision psychiatry — not open opps
A11: S07 | B11: USASpending API | C11: Federal portal | D11: Awarded federal grants/contracts | E11: Free, no auth | F11: REST API | G11: https://api.usaspending.gov/ | H11: Continuous | I11: Easy | J11: Med | K11: Competitive intel on NIH/NSF awards
A12: S08 | B12: ARPA-H Open Funding + Vitals newsletter | C12: Federal portal | D12: ARPA-H ISOs/programs/BAAs | E12: Free | F12: HTML + newsletter | G12: https://arpa-h.gov/explore-funding/open-funding-opportunities | H12: As announced | I12: Hard (use Grants/SAM API) | J12: High | K12: Subscribe Vitals; ARPA-H also posts to Grants.gov/SAM
A13: S09 | B13: EU Funding & Tenders Portal (SEDIA) | C13: Intl portal | D13: Horizon Europe, EIC, ERC, MSCA | E13: Free | F13: REST API + bulk CSV | G13: https://ec.europa.eu/info/funding-tenders/opportunities/data/topic-list.html | H13: Per cycle | I13: Medium | J13: Med | K13: US as consortium partner; keywords health/AI/mental
A14: S10 | B14: UKRI Funding Finder + GtR API | C14: Intl portal | D14: UK research councils + Innovate UK | E14: Free | F14: GtR-2 API (funded) + HTML (open) | G14: https://gtr.ukri.org/api/ | H14: Continuous | I14: Medium | J14: Low-Med | K14: Open calls are HTML scrape; US needs UK partner
A15: S11 | B15: ARIA (UK) funding opportunities | C15: Intl portal | D15: UK ARPA: high-risk programmes + seeds | E15: Free | F15: HTML + email + substack | G15: https://www.aria.org.uk/funding-opportunities/ | H15: Irregular | I15: Hard | J15: Med | K15: Subscribe ariaresearch.substack.com; also UK Find a Grant
... A34: S30 | B34: Hugging Face / Mozilla MOSS / Lambda / Together | C34: Compute rails | D34: Open-model compute + OSS support | E34: Free–credits | F34: HTML/forms | G34: https://huggingface.co/ | H34: Rolling | I34: Easy (apply) | J34: Med | K34: Gemma-class Cytonome inference + OSS support

Sheet PAC & Advocacy
A1: PAC & Advocacy — Companion List
A2: Patient Advocacy Council / partnership targets (separate from funders). OneMind is cross-listed in Master (F019/F051).
A4: ID | B4: Organization | C4: Primary role for Cytognosis | D4: Mission focus | E4: Lived-experience governance | F4: Geography | G4: Engagement / contact path | H4: Also funder/accelerator? | I4: PAC fit (0-10) | J4: Primary URL | K4: Conf.
A5: P01 | B5: OneMind | C5: Dual/tri-use: funder + accelerator + PAC model | D5: MH-broad / severe MH / innovation | E5: Strong — OMLEC council co-reviews grants; OMCAN community network | F5: National (Menlo Park / Napa — Bay-adjacent) | G5: Carmine Di Maro (ED); CSO Tahilia Rebello; engage OMLEC | H5: Yes — Rising Star grants + Accelerator | I5: 9 | J5: https://onemind.org | K5: High
A6: P02 | B6: DBSA (Depression and Bipolar Support Alliance) | C6: PAC seat candidate + model-to-emulate | D6: Mood disorders / peer-run | E6: Strong — chapters peer-run by people with lived experience | F6: National (Chicago HQ; Bay chapters) | G6: dbsalliance.org/contact; invite peer leader to PAC | H6: No | I6: 8 | J6: https://www.dbsalliance.org | K6: High
A7: P03 | B7: Autistic Self Advocacy Network (ASAN) | C7: PAC seat candidate + ND-led model | D7: Neurodivergence / autism / disability rights | E7: Strong — autistic-run; CBPR; 'Nothing About Us, Without Us' | F7: National (DC) | G7: autisticadvocacy.org/about-asan/contact; ND seat | H7: No | I7: 8 | J7: https://autisticadvocacy.org | K7: High
A8: P04 | B8: NAMI San Francisco | C8: PAC seat candidate + Bay-area anchor | D8: MH-broad / BIPOC equity / young adults | E8: Some — Youth Council (lived experience); Diversity cmte | F8: SF Bay Area | G8: aisha@namisf.org (Youth); anne@namisf.org (Diversity) | H8: No | I8: 7 | J8: https://www.namisf.org | K8: High
A9: P05 | B9: Fountain House | C9: Model-to-emulate (member-led research) | D9: Serious mental illness / clubhouse | E9: Strong — RAKE dept runs participatory research WITH members | F9: National (NY; CA Clubhouse Intl affiliates) | G9: fountainhouse.org/contact; CBPR consult; member-researcher seat | H9: No | I9: 7 | J9: https://www.fountainhouse.org | K9: High
A10: P06 | B10: Hopelab | C10: Model-to-emulate + co-research partner | D10: Digital MH / youth / LGBTQ+ / equity | E10: Strong — youth share decision-making incl. strategy/finance | F10: SF Bay Area (San Francisco) | G10: hopelab.org/contact; youth-seat pipeline; co-research | H10: Investor/convener | I10: 7 | J10: https://hopelab.org | K10: High
A11: P07 | B11: NAMI National | C11: Advocacy partner + recruitment channel | D11: MH-broad / SMI / family | E11: Strong — Peer Leadership Council; NAMI Next Gen youth | F11: National (Arlington VA) | G11: partnership@nami.org; MOU for recruitment | H11: No | I11: 6 | J11: https://www.nami.org | K11: High
A12: P08 | B12: Mental Health America (MHA) | C12: Advocacy partner + model (Position Stmt 63) | D12: MH-broad / peer support / policy | E12: Strong — PWLE on board; mandates PWLE on governance | F12: National + 200+ affiliates (CA) | G12: partnerships@mhanational.org; cite Pos. Stmt 63 in PAC charter | H12: Occasional small grants | I12: 6 | J12: https://mhanational.org | K12: High
A13: P09 | B13: Born This Way Foundation | C13: Youth advisory model + advocacy | D13: Youth MH / kindness / LGBTQ+ | E13: Strong — Global Youth Advisory Board co-shapes programs | F13: National (Boston; LA/NYC ops) | G13: bornthisway.foundation/advisory-board-application | H13: No | I13: 6 | J13: https://bornthisway.foundation | K13: High
A14: P10 | B14: Patient-Led Research Collaborative (PLRC) | C14: Governance template for the PAC | D14: Patient-led research governance | E14: Strong — patient-led research org; binding governance model | F14: National / virtual | G14: Study their charter; adapt PAC binding-governance structure | H14: No | I14: 7 | J14: https://patientresearchcovid19.com | K14: Med
A15: P11 | B15: 988 / SPRC Lived Experience Committees | C15: Governance precedent | D15: Suicide prevention / crisis | E15: Strong — formal lived-experience advisory committees | F15: National (federal) | G15: Model binding-council language from their charters | H15: No | I15: 6 | J15: https://988lifeline.org/988lifeline-committees/lived-experience-committee/ | K15: Med
... A30: P26 | B30: Sarika Agrawal (individual connector) | C30: Connector node → BRAIN Foundation + SFASA + autism PAC seats | D30: Autism / NDD (parent-advocate) | E30: n/a (individual) | F30: SF Bay | G30: Send the drafted email (friend of Ananth) | H30: No | I30: — | J30: https://www.linkedin.com/in/sarika-agrawal-573a/ | K30: High

Sheet Wave Action Plan
A1: Wave Action Plan
A2: The single next action per priority target, in time order. Colours match the Master 'Wave' column.
A4: Wave | B4: Window | C4: Opportunity | D4: Single next action | E4: Owner | F4: Hard date / cadence | G4: FitScore ref
A5: 0 | B5: DONE | C5: SAM.gov / Grants.gov registration (UEI/SAM) | D5: ✓ COMPLETE — UEI / SAM.gov account + identifiers already in hand | E5: Ops | F5: Done | G5: prereq
A6: 0 | B6: NOW | C6: Wellcome Leap HBNet | D6: Email HBNet@wellcomeleap.org; sign MARFA/CORFA | E6: PI | F6: This week | G6: F005
A7: 0 | B7: NOW | C7: Convergent Research FRO | D7: Submit 2-3pg Cytoverse FRO abstract | E7: PI | F7: This week (rolling) | G7: F006
A8: 0 | B8: NOW | C8: Anthropic AI for Science / NAIRR / Cohere | D8: Submit credit + compute applications (rolling) | E8: Eng | F8: This week | G8: F007/F008/F017
A9: 0 | B9: ≤1 wk | C9: AWS Imagine Pathfinder | D9: Submit Round-1 application | E9: PI | F9: 2026-06-05 | G9: F003
A10: 0 | B10: ≤2 wk | C10: NIMH BRAIN U01 (RFA-MH-26-140) | D10: Decide go/no-go; line up clinical co-PI; draft | E10: PI | F10: 2026-06-15 | G10: F002
A11: 0 | B11: ≤4 wk | C11: ARPA-H IGoR | D11: Draft + submit Solution Summary | E11: PI | F11: 2026-06-25 | G11: F001
A12: 0 | B12: ≤6 wk | C12: NSF X-Labs Topic 1 (Phase 0) | D12: Finish 8-pg proposal w/ Hervé Marie-Nelly | E12: PI | F12: 2026-07-13 | G12: F004
A13: 1 | B13: 1-3 mo | C13: ARPA-H PHO + HSF ISOs | D13: Submit Solution Summaries (rolling) | E13: PI | F13: June–July | G13: F009/F010
A14: 1 | B14: 1-3 mo | C14: NIMH R21 + R24 + R34 | D14: Pick one; draft for next standard date | E14: PI | F14: Jun 18 / Jun 25 / Oct | G14: F011/F012/F013
A15: 1 | B15: 1-3 mo | C15: Emergent Ventures | D15: Email 1-pg pitch (bridge funding) | E15: PI | F15: Rolling | G15: F014
... A27: 3 | B27: 6-18 mo | C27: EU Horizon Cluster 1 (2027) | D27: Join EU consortium as 3rd-country partner | E27: PI | F27: 2027-02 calls | G27: F053

Sheet Network & Warm-Intro Map
A1: Network & Warm-Intro Map
A2: People -> what they unlock -> warmth -> next action. F-IDs reference the Master sheet. Sensitive ties flagged.
A4: Person | B4: Role / Affiliation | C4: Relationship to Cytognosis | D4: Orgs / Opportunities it unlocks | E4: Warmth | F4: Suggested next action | G4: Conf.
A5: Ananth Grama | B5: Director, Purdue Institute for Physical AI (IPAI); Prof. CS | C5: Cytognosis Board co-chair; PhD advisor; active subaward channel | D5: Eli Lilly LRAP/LPRC/Catalyze360/Ventures; Mayo; Purdue subaward (F066-F068, F072-F073) | E5: Warm | F5: Ask him to broker a Lilly scientist co-sponsor (LRAP) + a Mayo Platform intro | G5: High
A6: Manolis Kellis | B6: Prof., MIT CSAIL / Broad Institute | C6: PI's postdoc advisor; PI = unpaid associated scientist — sensitive dynamics | D6: Jordan Smoller (joint grants); MIT/Broad networks; cross-disorder science | E6: Warm (handle sensitively) | F6: Navigate the dynamic before invoking; leverage via the co-advised postdoc | G6: High
A7: Jordan Smoller | B7: Dir., MGH Center for Precision Psychiatry; co-chair PGC Cross-Disorder Workgroup | C7: Network via Manolis + a co-advised postdoc shadowing bipolar meetings; cornerstone author | D7: MGH precision psychiatry; PGC cross-disorder data; Center for Digital MH adjacency; DSM Biomarkers (F079, F082, F089) | E7: Medium | F7: Warm intro via Manolis/postdoc; explore PGC data + co-authorship | G7: High
A8: Panos Roussos | B8: Dir., Center for Disease Neurogenomics, Mt Sinai; PsychENCODE/CommonMind PI | C8: Prior collaborator on multi-cohort SCZ/BD studies | D8: PsychENCODE/CMC open data (Synapse); Mt Sinai engagement; BD² (F088) | E8: Medium-Warm | F8: Reconnect re: joint multiscale analysis on the PsychENCODE atlases | G8: High
A9: Milad Alucozai | B9: Wyss (Harvard) mentor; GP, Pamir Ventures; ARPA-H Expert-in-Residence | C9: Friend of Ananth; prior outreach email drafted | D9: ARPA-H navigation; Wyss network; advisory/VC (note: Pamir is B2B-AI, not neuro) | E9: Medium | F9: Follow up the prior email; tap ARPA-H/Wyss network + advisory | G9: High
A10: Hani Goodarzi | B10: Core Investigator, Arc Institute (Virtual Cell); Assoc. Prof., UCSF | C10: Same high-school (Iran) tie | D10: Arc Virtual Cell alignment; Arc Alzheimer's Disease Initiative (seeking external collaborators) (F042, F058) | E10: Medium | F10: Reconnect; propose Cytoverse × Arc virtual-cell / AD collaboration | G10: High
A11: Angela Oliveira Pisco | B11: Director of Data Science, Chan Zuckerberg Initiative (CZI); ex-insitro | C11: Former manager at insitro — warm | D11: CZI Science grants; CZI AI/GPU + EOSS; CELLxGENE / cell-atlas co-development (F023, F024) | E11: Warm | F11: Reconnect re: CZI compute/EOSS + the cell-atlas layer of Cytoverse | G11: High
A12: Sarika Agrawal | B12: Co-founder & Board, BRAIN Foundation; Board, Autism Society SF Bay (SFASA) | C12: Friend of Ananth; has an autistic child; prior email drafted | D12: BRAIN Foundation grant; autism advocacy; PAC seats (autism/ND) (F074, F077) | E12: Warm | F12: Send the drafted email; explore BRAIN Foundation + SFASA + PAC seats | G12: High (affiliations verified)
A13: Hervé Marie-Nelly | B13: Founder, stealth co. (ex-insitro colleague) | C13: NSF X-Labs co-submitter | D13: NSF X-Labs Phase 0 (F004) | E13: Warm | F13: Finalize the joint X-Labs proposal (Jul 13) | G13: High
A14: Pramila Srinivasan | B14: President, BRAIN Foundation (Purdue PhD) | C14: Verified Purdue tie at the BRAIN Foundation | D14: BRAIN Foundation (F074) | E14: Medium | F14: Purdue/Ananth-adjacent intro to BRAIN Foundation leadership | G14: Med
A15: Madhvi Menon | B15: UK autoimmune lead, Cytognosis; UKRI Future Leaders Fellow, Univ. of Manchester | C15: Team member — the UK anchor | D15: UKRI/MRC (UK-funded PI route); Horizon Cluster 1 + EP PerMed (UK is Horizon-associated → funded coordinator); possible HBNet route; UK office (F053, F090, F091) | E15: Warm | F15: Map UKRI calls to her FLF; position Manchester as the EU/UK consortium anchor | G15: High
